
作者：禅与计算机程序设计艺术                    

# 1.背景介绍


Java程序在运行时可能会遇到各种各样的错误、异常情况。如果不加以处理，程序会终止运行或者表现出奇怪的行为。在Java中，异常处理就是用来对这些异常进行处理，从而使程序能按照预期正常执行。本教程将阐述Java中的异常处理机制，主要包括两种类型：Checked Exception（受检异常）和Unchecked Exception（非受检异常）。并通过实际例子来详细讲解如何处理异常，提高程序的鲁棒性。

# 2.核心概念与联系
## 2.1 Checked Exception与Unchecked Exception
Checked Exception（受检异常）：包括IOException，SQLException等，这种异常需要捕获并处理，否则程序无法继续执行。比如，用户可能由于输入错误导致程序崩溃，或者数据库连接失败等；

Unchecked Exception（非受检异常）：除此之外的所有异常都是Unchecked Exception，比如NullPointerException，IndexOutOfBoundsException，IllegalArgumentException，UnsupportedOperationException等；

Checked Exception vs Unchecked Exception: 

Checked Exception 和 Unchecked Exception之间的区别在于，前者要求必须处理掉这个异常，也就是说程序运行过程中需要对它进行处理，否则不能正常运行，后者不需要处理也能正常运行。例如，如果某个方法声明抛出IOException，那么调用该方法的程序就需要处理这个异常，否则编译无法通过；而其他一些异常虽然很容易出现，但是由于逻辑错误或者临时的偶然性，可能难以恢复或处理，所以一般是用Unchecked Exception来表示。

对于Checked Exception来说，处理方式通常为try...catch块或者throws语句，可以选择捕获处理还是直接向上层抛出；对于Unchecked Exception来说，因为没有强制要求一定要处理它们，因此也可以选择忽略，比如在catch块中只记录日志信息而不做任何处理；

## 2.2 try...catch块
try…catch块是一个异常处理结构，其基本语法如下：

```java
try {
   //可能发生异常的代码
} catch (ExceptionType e) {
   //捕获异常的处理代码
} finally {
   //finally块用于释放资源、关闭流等
}
```

其中，try块用来包含可能出现异常的代码，catch块用来捕获可能发生的特定类型的异常，当该类型异常发生时，控制权就会转移到catch块进行处理。

举个例子：

```java
public class Example {
    public static void main(String[] args) throws IOException {
        BufferedReader reader = new BufferedReader(new FileReader("input.txt"));

        while (true) {
            String line = null;

            try {
                line = reader.readLine();

                if (line == null) {
                    break;
                } else {
                    System.out.println(line);
                }
            } catch (IOException ex) {
                System.err.println("Error reading file: " + ex.getMessage());
                throw ex;
            }
        }

        reader.close();
    }
}
```

如上的示例程序，程序读取一个文件的内容并打印出来。为了保证每次读取的行数正确，使用了一个while循环一直读取直至读不到更多的行。在try块内，使用了BufferedReader类的readLine()方法来读取每一行文本。

当readLine()方法抛出IOException时，会自动被捕获并进入catch块进行处理。首先，输出一条错误消息；然后，再次把异常抛给调用者。这样，如果调用者没有处理IOException，就会把异常传播给更高层级，让程序终止执行。

finally块可用于释放资源或者关闭流，无论是否出现异常都必须执行。

## 2.3 Throwable类及其子类
Throwable类是所有异常的父类，它提供了两个常用的方法：printStackTrace()和getMessage()。printStackTrace()用来输出异常的堆栈信息，getMessage()则用来获取异常的信息。Throwable还有三个子类分别对应不同的异常类型：

- Error: 表示错误异常，表示虚拟机的内部错误或者资源耗尽。
- RuntimeException: 表示运行时异常，是程序的逻辑错误或者编码错误引起的异常。
- Throwable: 抽象类，继承自Object类，用于定义所有 throwable 对象共有的属性和方法。

下图展示了Throwable及其子类的继承关系。



# 3.核心算法原理和具体操作步骤以及数学模型公式详细讲解
## 3.1 为什么要学习异常处理？
异常是Java编程中不可忽视的一部分，它承担着编写健壮、稳定、可维护的重要作用。良好的异常处理机制能够帮助我们快速定位并解决程序中的错误，提升程序的运行效率、简化开发过程。因此，掌握Java异常处理机制，对于Java开发人员来说，无疑是非常必要的。

## 3.2 异常处理的方式
异常处理的方式主要有三种：

1. try…catch…finally块：这是最常用的异常处理方式。它允许您将可能产生异常的代码放在try块中，并指定异常类型和相应的处理动作放在对应的catch块中。一旦try块中的代码发生异常，JVM就会寻找匹配的catch块进行处理。如果仍然没有找到匹配的catch块，JVM就会报出未处理的异常，这时可以在finally块中进行一些资源清理工作，如关闭流、释放内存等。
2. throws关键字：当函数的实现中调用另一个函数时，可以使用throws关键字声明该函数可能会抛出的异常。调用者可以选择捕获或者忽略这些异常。
3. 自定义异常类：除了由系统定义的异常类以外，开发者还可以创建自己的异常类。每个异常类都应该继承自Throwable类并提供必要的构造器和方法。

总结一下，异常处理的三种方式如下：

- 使用try…catch…finally块：适合处理简单的异常场景，可以精确地定位异常位置，而且可以在处理异常时对程序进行干预。
- 使用throws关键字：适合处理复杂的异常场景，可以明确地指定一个函数可能会抛出的异常，避免调用者感知不到的异常。
- 创建自定义异常类：灵活地处理不同类型的异常，可以基于已有的异常类进行扩展，根据需求设计新的异常类。

## 3.3 异常处理原则
异常处理的原则如下：

1. 对抗原则：异常处理机制应当对抗错误造成的系统崩溃，因此在设计异常处理时，应当尽量减少对业务逻辑的影响，使得异常处理起来更加安全和可靠。
2. 隔离原则：多个模块之间不共享异常处理机制，不同模块的异常处理方案应当相互独立，方便维护和升级。
3. 封装原则：异常处理机制应当封装细节，暴露接口而不是隐藏细节，方便调用者进行处理。

## 3.4 异常分类
一般情况下，异常分为两种类型：Checked Exception（受检异常）和Unchecked Exception（非受检异常）。

Checked Exception（受检异常）：表示代码运行中可能出现的错误，是一种编译时错误，必须在源代码处进行处理。主要的 Checked Exception 包括IOException，SQLException等。

Unchecked Exception（非受检异常）：表示运行时错误，是一种运行时错误，不会造成程序的崩溃，必须在运行时检测和处理。主要的 Non-Checked Exception 包括 NullPointerException，IndexOutOfBoundsException，IllegalArgumentException，UnsupportedOperationException等。

另外，Exception也是一种受检异常，因为它也是一种异常。如果不处理的话，系统会自动把它抛给它的上层调用者，直到找到能够处理它的地方为止。

## 3.5 抛出异常
Java 提供了三种方式来抛出异常：

1. 通过throw语句手动抛出异常。
2. 抛出已检查异常。
3. 抛出未检查异常。

### 3.5.1 通过throw语句手动抛出异常
通过throw语句手动抛出异常，需要注意以下几点：

1. 可以通过throw关键字手动抛出任意一个 Throwable 的子类对象作为异常对象，即可以手动抛出自己定义的异常类、系统预定义的异常类、RuntimeException 类等。
2. 在抛出异常的时候，可以带上详细的异常信息，这样在程序出错时可以提供更加详细的信息帮助开发人员定位异常。
3. 如果不想让上层调用者看到异常的具体信息，可以选择隐藏具体信息，只保留异常类名即可。

抛出一个异常的例子：

```java
class MyException extends Exception{
  public MyException(){
    super("自定义异常");
  }
  
  public MyException(String message){
    super(message);
  }
}

public class MainClass {

  public static void main(String[] args) {

    int a = 10 / 0;
    
    try{
      if(a > 0){
        throw new IllegalArgumentException("参数异常");
      }else{
        throw new MyException("自定义异常");
      }
      
    }catch(IllegalArgumentException e){
      System.out.println("参数异常：" + e.getMessage());
      
    }catch(MyException e){
      System.out.println("自定义异常：" + e.getMessage());
    }
    
  }
  
}
```

在main()方法中，我先用int型变量a赋值为10，然后又尝试将其赋值为零，触发异常，此时就会抛出IllegalArgumentException。由于这是一个已检查异常，所以我用一个catch块捕获到了这个异常，打印了错误信息。接着，我再次触发MyException异常，同样也用一个catch块捕获到了异常，并打印了自定义的错误信息。

输出结果：

```
java.lang.ArithmeticException: division by zero
参数异常：参数异常
自定义异常：自定义异常
```

### 3.5.2 抛出已检查异常
通过关键字 throws 来声明一个方法可能抛出的已检查异常，然后用 try … catch … finally 块来捕获并处理异常。如果某个方法可能抛出多个已检查异常，可以像下面一样列出多个异常类型，中间用逗号隔开。

语法形式：

```java
void method() throws ExceptionType1, ExceptionType2,...
```

注意事项：

- 方法体内，通过抛出已检查异常的语句，只能抛出其子类对象，不能抛出Throwable类对象，否则将报错。
- 如果在 try 块中调用一个声明了throws E1,E2,...的方法，则该方法的调用者必须提供与该方法相同的异常处理机制。

举例：

```java
public class Calculator {

   public double divide(double numerator, double denominator) throws ArithmeticException {

      return numerator / denominator;
   }
   
   public int add(int x, int y) throws MyException {

      return x + y;
   }

}
```

如上面的例子所示，Calculator类中声明了两个方法divide()和add()，两个方法均存在可能抛出的已检查异常。divide()方法的计算结果为浮点型数据，可能会出现除数为零的异常，所以该方法声明抛出ArithmeticException。add()方法的计算结果为整形数据，可能会出现参数异常，所以该方法声明抛出MyException。

测试代码：

```java
import java.util.Scanner;

public class TestExceptions {

   public static void main(String[] args) {

      Scanner scanner = new Scanner(System.in);
      
      System.out.print("Enter the first number:");
      double numerator = scanner.nextDouble();
      
      System.out.print("Enter the second number:");
      double denominator = scanner.nextDouble();
      
      try {
         
         double result = new Calculator().divide(numerator, denominator);
         System.out.println("Result of division is:" + result);
         
         int sum = new Calculator().add((int)(result * 10), 20);
         System.out.println("Sum is:" + sum);
         
      } catch (ArithmeticException ae) {

         System.out.println("Exception occurred in divide()");
         
      } catch (MyException me) {

         System.out.println("Exception occurred in add()");
      }
      
      scanner.close();
   }
}
```

如上面的测试代码中，我使用了Scanner来获取两个数字进行计算，分别测试divide()方法和add()方法。如果调用方法过程中抛出异常，则会跳转到相应的catch块进行处理。这里，我分别处理了两种异常，打印了对应的错误信息。

如果没有异常抛出，则返回的结果将作为参数传入到相关的方法进行处理。

测试结果：

```
Enter the first number:10
Enter the second number:2
Result of division is:5.0
Sum is:70
```

```
Enter the first number:10
Enter the second number:0
Exception occurred in divide()
```

```
Enter the first number:abc
Enter the second number:2
Exception in thread "main" java.util.InputMismatchException
	at java.util.Scanner.throwFor(Unknown Source)
	at java.util.Scanner.hasNext(Unknown Source)
	at java.util.Scanner.nextInt(Unknown Source)
	at java.util.Scanner.nextInt(Unknown Source)
	at TestExceptions.main(TestExceptions.java:14)
Caused by: java.util.NoSuchElementException
	at java.util.Scanner.throwFor(Unknown Source)
	at java.util.Scanner.hasNext(Unknown Source)
	... 3 more
```

如上面的输出结果所示，第一组输出结果是在正常的运行过程中，程序抛出了除零异常，导致程序退出；第二组输出结果是在调用divide()方法中，由于除法运算错误，导致程序异常退出；第三组输出结果是在调用add()方法中，由于类型转换失败，导致程序异常退出。

### 3.5.3 抛出未检查异常
在Java中，所有的异常都继承自Throwable类。Throwable类是抽象类，定义了一系列的异常。不过，Throwable 类本身可以作为父类，但绝大多数开发人员习惯于抛出一个子类异常来描述自己的异常情况，因此，推荐使用 Checked Exception 。

一般情况下，应用程序中的代码需要捕获并处理某些特定类型异常。对于那些未检查异常，如果不加以处理，程序会终止运行。

举例：

```java
public class RandomNumberGenerator {

   private final static SecureRandom random = new SecureRandom();

   public static int generate() {
      return random.nextInt(100) + 1;
   }

}
```

如上面的例子所示，RandomNumberGenerator类是一个随机数生成器，可以通过generate()方法来产生一个随机整数。由于随机数生成是安全的，因此该方法没有抛出任何异常。但是，random.nextInt(100)方法可能会抛出IllegalArgumentException，因为nextInt()的参数必须介于0和bound-1之间，如果不满足条件，就会抛出IllegalArgumentException。

为了处理这一异常，可以在调用nextInt()之前添加一个try…catch块，捕获该异常，并进行相应的处理。

```java
public class RandomNumberGenerator {

   private final static SecureRandom random = new SecureRandom();

   public static int generate() {
      int bound = 100;
      int value = -1;
      boolean success = false;

      do {
         try {
            value = random.nextInt(bound);
            success = true;
         } catch (IllegalArgumentException e) {
            bound--; // reduce range and retry
         }
      } while (!success && bound >= 1);

      if (!success) {
         throw new IllegalStateException("Failed to generate a random integer.");
      }

      return value;
   }

}
```

如上面的更新后的代码，在生成随机数时，程序会尝试生成一个范围在[1, 100]之间的整数。如果nextInt()方法抛出IllegalArgumentException，则说明该值超出了范围限制，程序会将范围缩小一半并重新生成随机数，直至成功为止。

最后，程序会判断是否成功生成随机数，若成功，则返回该值；否则，会抛出IllegalStateException，提示失败原因。

## 3.6 捕获异常
在使用try…catch…finally块时，捕获异常的顺序应该按照throws子句中异常的继承顺序进行排序，以便最底层的异常优先处理。

## 3.7 try…catch…finally与return关键字的关系
当方法执行完毕后，自动执行finally块中的代码，然后返回方法调用处，结束方法的执行。因此，如果finally块中包含return语句，则覆盖了方法的正常返回值。

另外，如果在finally块中抛出了异常，则这个异常会被丢弃，而且不会传递到调用者。如果希望在finally块中抛出一个异常，可以通过Thread.currentThread().getUncaughtExceptionHandler().uncaughtException()方法来设置线程的默认异常处理器。

## 3.8 自定义异常类
自定义异常类往往需要继承自Exception类或者其子类，并提供必要的构造器和方法。例如，创建一个名字长度超过限制的自定义异常类NameTooLongException。

```java
public class NameTooLongException extends Exception {

   /**
    * Create a new instance with an error message.
    */
   public NameTooLongException(String name) {
      super("Name too long (" + name.length() + "): " + name);
   }

}
```

这个自定义异常类继承自Exception类，提供了单一的构造器，接收一个字符串类型的姓名参数。在构造器中，生成了一个包含姓名长度和姓名的异常信息。通过覆写toString()方法，可以获得这个异常的详细信息。

使用自定义异常类的例子：

```java
public class Person {

   protected String firstName;
   protected String lastName;

   public void setFirstName(String firstName) {
      this.firstName = firstName;
   }

   public void setLastName(String lastName) {
      if (lastName!= null && lastName.length() > 50) {
         throw new NameTooLongException(lastName);
      }
      this.lastName = lastName;
   }

}
```

如上面的例子所示，Person类有一个firstName和lastName字段，分别代表人物的名字。setLastName()方法用来设置姓氏，如果姓氏长度超过50个字符，就会抛出NameTooLongException。调用方需要捕获该异常并处理。

```java
Person person = new Person();
person.setLastName("thisnameiswaytoolongfortheylline");

// This will not be reached because setName throws an exception
System.out.println(person.getLastName());
```

如上面的测试代码中，设置了一个姓名过长的姓氏，并试图取得LastName的值，但是由于LastName的值已经被设置为null，所以会抛出空指针异常。通过自定义的NameTooLongException，可以捕获这个异常并向调用者提供有意义的错误信息。