                 

# 1.背景介绍

协程（coroutine）是一种轻量级的用户级线程，它们可以在同一时间内运行多个同步操作。协程的出现为了解决传统线程的并发模型的一些局限性，例如线程的创建和销毁开销较大，线程之间的通信和同步开销较大，线程数量有限等问题。

在实际应用中，协程在处理错误时会遇到一些挑战。协程的错误处理机制与传统的异常处理机制有所不同，因此在使用协程时需要了解其错误处理的最佳实践。

本文将从以下几个方面进行阐述：

1. 背景介绍
2. 核心概念与联系
3. 核心算法原理和具体操作步骤以及数学模型公式详细讲解
4. 具体代码实例和详细解释说明
5. 未来发展趋势与挑战
6. 附录常见问题与解答

## 1.背景介绍

协程的错误处理主要包括以下几个方面：

- 如何在协程中捕获和处理错误？
- 如何在协程之间传递错误信息？
- 如何在协程中处理异步操作的错误？

为了解决这些问题，我们需要了解协程的错误处理机制，并学会使用合适的技术手段。

在传统的异常处理机制中，异常是在运行时由程序或操作系统发生的不期望的事件。异常可以在程序运行过程中捕获和处理，以避免程序崩溃或者继续运行。

协程的错误处理机制与传统异常处理机制有所不同。协程的错误处理主要通过返回错误信息和错误代码来实现。当协程遇到错误时，它会返回一个错误信息和错误代码，然后将控制权传递给调用者。调用者可以根据错误信息和错误代码来处理错误。

在实际应用中，协程的错误处理机制与传统的异常处理机制有所不同，因此在使用协程时需要了解其错误处理的最佳实践。

## 2.核心概念与联系

在协程的错误处理中，我们需要了解以下几个核心概念：

- 错误信息：协程遇到错误时，会返回一个错误信息，用于描述错误的具体原因。
- 错误代码：协程遇到错误时，会返回一个错误代码，用于描述错误的类型。
- 错误处理函数：协程的错误处理函数用于处理协程遇到的错误，并根据错误信息和错误代码来决定下一步的操作。

这些核心概念与传统的异常处理机制有所不同，因此在使用协程时需要了解其错误处理的最佳实践。

## 3.核心算法原理和具体操作步骤以及数学模型公式详细讲解

在协程的错误处理中，我们需要了解以下几个核心算法原理和具体操作步骤：

1. 在协程中捕获和处理错误：

当协程遇到错误时，它会返回一个错误信息和错误代码。调用者可以根据错误信息和错误代码来处理错误。例如，我们可以使用一个错误处理函数来处理协程遇到的错误。

2. 在协程之间传递错误信息：

在协程之间传递错误信息可以通过返回值、异步操作等方式实现。例如，我们可以使用一个错误处理函数来处理协程之间传递的错误信息。

3. 在协程中处理异步操作的错误：

在协程中处理异步操作的错误可以通过异步操作的回调函数、异步操作的错误处理函数等方式实现。例如，我们可以使用一个错误处理函数来处理协程中异步操作的错误。

数学模型公式详细讲解：

在协程的错误处理中，我们可以使用以下数学模型公式来描述错误信息和错误代码：

- 错误信息：E = {e1, e2, ..., en}
- 错误代码：C = {c1, c2, ..., cm}

其中，E表示错误信息，C表示错误代码，e1、e2、...,en表示错误信息，c1、c2、...,cm表示错误代码。

具体操作步骤：

1. 在协程中捕获和处理错误：

当协程遇到错误时，它会返回一个错误信息和错误代码。调用者可以根据错误信息和错误代码来处理错误。例如，我们可以使用一个错误处理函数来处理协程遇到的错误。

2. 在协程之间传递错误信息：

在协程之间传递错误信息可以通过返回值、异步操作等方式实现。例如，我们可以使用一个错误处理函数来处理协程之间传递的错误信息。

3. 在协程中处理异步操作的错误：

在协程中处理异步操作的错误可以通过异步操作的回调函数、异步操作的错误处理函数等方式实现。例如，我们可以使用一个错误处理函数来处理协程中异步操作的错误。

## 4.具体代码实例和详细解释说明

在本节中，我们将通过一个具体的代码实例来说明协程的错误处理的最佳实践。

```python
import asyncio

async def main():
    try:
        result = await asyncio.wait([func1(), func2()])
    except Exception as e:
        print(f"协程遇到错误：{e}")

async def func1():
    try:
        raise ValueError("func1 遇到错误")
    except ValueError as e:
        return {"error": str(e)}

async def func2():
    try:
        raise TypeError("func2 遇到错误")
    except TypeError as e:
        return {"error": str(e)}

if __name__ == "__main__":
    asyncio.run(main())
```

在上述代码中，我们定义了三个协程：main、func1和func2。主协程main通过await调用了func1和func2，并使用try-except语句来捕获它们遇到的错误。当func1和func2遇到错误时，它们会返回一个错误信息，并将控制权传递给调用者。调用者可以根据错误信息来处理错误。

在这个例子中，我们可以看到协程的错误处理机制与传统的异常处理机制有所不同。协程的错误处理主要通过返回错误信息和错误代码来实现，而不是通过异常来实现。

## 5.未来发展趋势与挑战

在未来，协程的错误处理技术将会不断发展和完善。我们可以预见以下几个方向：

1. 协程的错误处理机制将会越来越加普及，并成为编程中的一种常见技术手段。
2. 协程的错误处理技术将会不断发展，并为更多的应用场景提供更加高效和可靠的解决方案。
3. 协程的错误处理技术将会面临一些挑战，例如在并发操作较多的场景下，协程的错误处理效率和性能将会成为关键问题。

## 6.附录常见问题与解答

在本节中，我们将解答一些常见问题：

Q: 协程的错误处理与传统异常处理有什么区别？
A: 协程的错误处理主要通过返回错误信息和错误代码来实现，而不是通过异常来实现。

Q: 如何在协程之间传递错误信息？
A: 在协程之间传递错误信息可以通过返回值、异步操作等方式实现。

Q: 如何在协程中处理异步操作的错误？
A: 在协程中处理异步操作的错误可以通过异步操作的回调函数、异步操作的错误处理函数等方式实现。

Q: 协程的错误处理技术将会面临哪些挑战？
A: 协程的错误处理技术将会面临一些挑战，例如在并发操作较多的场景下，协程的错误处理效率和性能将会成为关键问题。

Q: 未来协程的错误处理技术将会发展哪些方向？
A: 在未来，协程的错误处理技术将会不断发展和完善，并为更多的应用场景提供更加高效和可靠的解决方案。