                 

# 1.背景介绍


## 为什么要写这篇文章？
我自己之前接触到一些Python库的时候，都会看到一些有关异常处理的操作或者函数，但是很少用到自己的实际应用场景中，所以一直都很疑惑这些工具到底能不能真正解决我们的开发问题。后来在了解Python异常处理机制之后，越发觉得它确实是一种非常好的工具。所以写这篇文章来总结一下Python异常处理机制的内容。

## 目标读者
本文是为了新手Python程序员设计的，主要面向具有一定编程基础的程序员。但是也适合对Python有一定的了解，但想进一步了解它的细节的人阅读。

# 2.核心概念与联系
## 异常（Exception）
异常（Exception）是程序运行时出现的不正常状态，比如除零错误、类型错误等。在Python中，当出现异常时，会抛出一个“异常对象”，这个对象中包含了异常信息，可以捕获并处理该异常。

## try...except...finally语句
try...except...finally语句是一个异常处理机制，用于处理可能出现的异常。其中try子句用来检测是否有异常发生；except子句用于捕获指定的异常，处理方式一般包括打印错误消息或者继续执行；finally子句用于保证程序执行的最后阶段，无论是否有异常发生都需要被执行。

## raise语句
raise语句用来引发或抛出一个异常，语法如下：
```python
raise Exception('Error message here') # 抛出一个Exception类型的异常
```

## traceback模块
traceback模块提供了跟踪栈信息的方法，可以帮助我们定位错误的位置。我们可以通过设置环境变量PYTHONTRACEBACKVERBOSE的值为1，开启更加详细的错误信息输出。

## assert语句
assert语句是一个条件判断语句，用于在程序运行时验证某些表达式的值，如果表达式的值为False，则触发AssertionError异常。

# 3.核心算法原理和具体操作步骤以及数学模型公式详细讲解
## try...except...finally语句基本语法
try:
    # 有可能会产生异常的代码
except ExceptionType as errorObject:
    # 如果在try块中的语句引发了指定的ExceptionType类型的异常，则将errorObject赋值给该异常对象
else:
    # 当没有异常发生在try块中的时候，则执行else语句块
finally:
    # 不管有没有异常发生都会执行此语句块

例如下面的代码片段展示了一个简单的程序：

```python
try:
    a = int(input("Enter the first number: "))
    b = int(input("Enter the second number: "))
    print("The sum is:", a + b)
except ValueError:
    print("Invalid input!")
finally:
    print("This code block will always execute")
```

在上面代码中，输入两个数字，然后打印它们的和。由于用户可能输入非整数值，因此在int()函数调用中可能会产生ValueError异常。这里通过except子句捕获到了该异常，并打印出了自定义的错误消息"Invalid input!"，还有一个finally子句保证了该语句块始终执行。

## raise语句的语法及作用
raise语句可以手动抛出一个异常，指定异常的类型以及错误信息。在使用第三方库时，也可以抛出其定义的异常类型。

举个例子，假设有一个自定义异常类MyError，希望在程序运行时抛出该异常，语法如下：

```python
class MyError(Exception):
    pass

def foo():
    if some_condition:
        raise MyError("Something went wrong")
    
try:
    foo()
except MyError as e:
    print(e)
```

以上代码中，定义了一个自定义异常类MyError，并且定义了一个函数foo，在该函数内部有一个判断条件some_condition，如果满足的话，就抛出一个新的MyError异常，并附带了相应的错误信息。在调用foo()时，如果捕获到了MyError异常，就可以做出相应的处理。

## assert语句的基本语法
assert语句的基本语法为：

```python
assert expression [, message]
```

expression表示要进行判断的表达式，message是可选参数，用于提供报错时的提示信息。当expression的值为True时，assert语句不会引发任何异常，否则会抛出AssertionError异常。

例如：

```python
a = "hello"
b = [1, 2, 3]
c = ""

assert isinstance(a, str), "a should be string type."
assert len(b) > 1, "b should have more than one element."
assert c!= "", "c cannot be empty."
```

上述代码首先声明了几个变量，然后通过三种不同的方式使用assert语句进行断言。第一种情况是检查变量a的类型，第二种情况是检查列表元素个数，第三种情况是检查变量c是否为空字符串。三个断言都只有在条件成立的情况下才不会报错，否则会抛出AssertionError异常。

## traceback模块的基本功能
traceback模块提供了获取跟踪栈信息的方法，可以帮助我们定位错误的位置。我们可以通过设置环境变量PYTHONTRACEBACKVERBOSE的值为1，开启更加详细的错误信息输出。

举例说明：

```python
import traceback

try:
    1 / 0
except ZeroDivisionError:
    print(traceback.format_exc())
```

输出：

```
  File "<ipython-input-7-d9db8d660a0f>", line 2, in <module>
    1/0
ZeroDivisionError: division by zero
```

从输出结果可以看出，该异常是在文件的第2行抛出的，并且具体的信息是“division by zero”。

# 4.具体代码实例和详细解释说明
## 用try...except...finally语句处理异常

### 基本示例
以下是一个简单的示例，演示如何使用try...except...finally语句处理异常。

```python
try:
    x = 1 / 0
except ZeroDivisionError as err:
    print(err)
finally:
    print("This code block will always execute")
```

输出：

```
division by zero
This code block will always execute
```

在上面的代码中，尝试执行1 / 0，这是一个表达式，表达式中存在除数为0的情况，引发了ZeroDivisionError异常。通过try...except...finally语句捕获到该异常，并打印出相关的错误信息，最后执行finally子句，无论是否有异常发生都会执行。

### 使用多个except语句处理多种异常

在同一个try...except...finally语句中可以根据不同类型的异常使用不同的except子句处理异常。

```python
try:
    x = 1 / 0
except ZeroDivisionError as zde:
    print(zde)
except TypeError as te:
    print(te)
finally:
    print("This code block will always execute")
```

在上面的代码中，尝试执行1 / 0，这是一个表达式，表达式中存在除数为0的情况，引发了ZeroDivisionError异常。由于缺乏对除数为0的处理，因此捕获不到该异常。通过第二个except子句处理TypeError异常。另外，仍然打印出默认的错误信息"division by zero"，并在finally子句中执行。

### 忽略某些异常

在某个位置捕获异常后，可以使用pass语句忽略该异常。

```python
try:
    x = 1 / 0
except ZeroDivisionError as zde:
    print(zde)
except (TypeError, NameError) as ne:
    pass
finally:
    print("This code block will always execute")
```

在上面的代码中，尝试执行1 / 0，这是一个表达式，表达式中存在除数为0的情况，引发了ZeroDivisionError异常。由于缺乏对除数为0的处理，因此捕获不到该异常。通过第一个except子句处理ZeroDivisionError异常，第二个except子句的括号内包含两个异常类型NameError和TypeError，因此会忽略所有的NameError和TypeError异常。

### 将捕获到的异常赋值给变量

可以在except子句中使用as关键字将捕获到的异常赋值给变量。

```python
try:
    x = 1 / 0
except ZeroDivisionError as zde:
    print(type(zde))
finally:
    print("This code block will always execute")
```

在上面的代码中，尝试执行1 / 0，这是一个表达式，表达式中存在除数为0的情况，引发了ZeroDivisionError异常。由于缺乏对除数为0的处理，因此捕获到了该异常。通过except子句捕获到该异常，并打印出异常的类型名称ZeroDivisionError。

### 案例：文件读取

以下是读取文件并打印文件的第一行的例子：

```python
filename = 'test.txt'

with open(filename) as f:
    content = f.readlines()
    for line in content:
        print(line.strip('\n'))
```

当打开的文件不存在时，open函数会抛出FileNotFoundError异常。为了避免这种异常导致程序崩溃，可以在打开文件时使用try...except...finally语句来处理异常。

```python
filename = 'test.txt'

try:
    with open(filename) as f:
        content = f.readlines()
        for line in content:
            print(line.strip('\n'))
except FileNotFoundError:
    print(f"{filename} not found.")
except IOError as ioe:
    print(ioe)
finally:
    print("This code block will always execute")
```

在上面的代码中，尝试打开文件‘test.txt’，如果文件不存在，则捕获到FileNotFoundError异常，并打印相应的错误信息；如果文件打开过程中出现IOError异常，则捕获到该异常，并打印相关的错误信息；无论是否有异常发生，都会执行finally子句。

### 案例：断言失败时触发异常

可以使用assert语句作为调试辅助工具，可以帮助检查程序中的逻辑错误。

```python
x = -1
y = 2

assert x >= 0, "x must be non-negative."

result = x ** y
print(result)
```

在上面的代码中，设置两个变量x和y。由于x小于等于0，因此触发AssertionError异常。通过设置环境变量PYTHONDEBUG值为1，可以打开python的debug模式，并获得更多的报错信息。

输出：

```
Traceback (most recent call last):
 ...
  AssertionError: x must be non-negative.
```

在上面的报错信息中，可以看到断言表达式‘x >= 0’失败了。

# 5.未来发展趋势与挑战
目前为止，我们已经对Python异常处理机制的基本概念、语法和操作有了一定的了解。

下一步，我们可以对异常处理机制进行扩展和深化，可以增加更多的异常类型，比如网络连接失败、数据库连接失败等。另外，还可以探索其他的异常处理机制，比如装饰器（decorator）来简化异常处理流程。